ERROR:root:test exception message:[1,3,6]
Traceback (most recent call last):
    File "<ipython-input-1-34a116fcf5db>", line 5, in <module>
      raise Exception
Exception